Workbook
Name copyright: About!$B$48
Name var_AAR: Variables!$C$5
Name var_averageCoC: Variables!$C$9
Name var_capRateBump: 'Exit Strategy'!$I$9
Name var_DSCR: Variables!$C$4
Name var_expensePercentage: Variables!$C$7
Name var_IRR: Variables!$C$6
Name var_operatingReserves: Variables!$C$11
Name var_returnCapitalPercentage: Variables!$C$8
Name var_totalLoan: Variables!$C$13
Name year_refi: 'Exit Strategy'!$D$4
Name year_sale: 'Exit Strategy'!$D$5

Sheet Welcome
B1: Welcome | C1: Version 2.9.4
B3: Welcome to the SYNDICATED DEAL ANALYZER software!
B5: I created the Syndicated Deal Analyzer software over many years and continued to improve it with every deal I analyzed. The primary difference between this analyzer and others you may have seen is that it incorporates other investors into all aspects of the deal, from analysis, to closing, to final disposition. It's designed to quickly do the easy things, but it also allows you to customize all of the assumptions and numbers, which is important as you discover new information during due diligence. I purposefully allow you to edit and customize EVERYTHING for two reasons: (1) so that you can understand the formulas to help you to learn and (2) so that you can make it look like you want. My goal with the Syndicated Deal Analyzer is to help you analyze deals faster and more accurately so that you can make more offers and do more deals.
B6: =HYPERLINK("https://courses.themichaelblank.com/users/sign_in","To get started, please watch the training videos, which you can access here.") -> To get started, please watch the training videos, which you can access here.
B7: If you'd like to get support and feedback of your analysis, please consider joining the Deal Maker's Mastermind. To your success!
B8: =HYPERLINK("http://www.themichaelblank.com/dmm","Learn More About the Deal Maker's Mastermind.") -> Learn More About the Deal Maker's Mastermind.
B12: To Your Success!
B18: The Michael Blank Team

Sheet About
B1: About
B3: Deal Readiness Dashboard
B4: Key Metric | C4: Minimum Criteria | D4: Actual | E4: Comments
B5: Debt Coverage Ratio (DCR) | C5: =IF($B$46=Variables!$E$27,Variables!C4,IF($B$46=Variables!$F$26,Variables!C4,Variables!D4)) -> 1.25 | D5: =Summary!D38 -> 0 | E5: =IF(D5=0,"",IF(D5<C5,Variables!E4,Variables!F4))
B6: Average Annual Return (AAR) | C6: =IF($B$46=Variables!$E$27,Variables!C5,IF($B$46=Variables!$F$26,Variables!C5,Variables!D5)) -> 0.15 | D6: =Summary!D48 -> 0 | E6: =IF(D6=0,"",IF(D6<C6,Variables!E5,Variables!F5))
B7: Internal Rate of Return (IRR) | C7: =IF($B$46=Variables!$E$27,Variables!C6,IF($B$46=Variables!$F$26,Variables!C6,Variables!D6)) -> 0.14 | D7: =Summary!D50 -> 0 | E7: =IF(D7=0,"",IF(D7<C7,Variables!E6,Variables!F6))
B8: Expenses | C8: =IF($B$46=Variables!$E$27,Variables!C7,IF($B$46=Variables!$F$26,Variables!C7,Variables!D7)) -> 0.5 | D8: =Summary!C32 -> 0 | E8: =IF(D8=0,"",IF(D8<C8,Variables!E7,Variables!F7))
B9: % of Capital Returned With Refinance | C9: =IF($B$46=Variables!$E$27,Variables!C8,IF($B$46=Variables!$F$26,Variables!C8,Variables!D8)) -> 0.6 | D9: =IF('Exit Strategy'!D4="NA","NA",'Exit Strategy'!D23) -> NA | E9: =IF(OR(D9=0,D9="NA"),"",IF(D9<C9,Variables!E8,Variables!F8))
B10: Cash-on-Cash Return (CoC) | C10: =IF($B$46=Variables!$E$27,Variables!C9,IF($B$46=Variables!$F$26,Variables!C9,Variables!D9)) -> 0.07 | D10: =Summary!D37 -> 0 | E10: =IF(D10=0,"",IF(D10<C10,Variables!E9,Variables!F9))
B11: Replacement Reserves | C11: =IF($B$46=Variables!$E$27,Variables!C10,IF($B$46=Variables!$F$26,Variables!C10,Variables!D10)) -> 0 | D11: ='P&L'!D32 -> 0 | E11: =IF(D5=0,"",IF(D11<C11,Variables!E10,Variables!F10))
B12: Reserves | C12: =IF($B$46=Variables!$E$27,Variables!C11,IF($B$46=Variables!$F$26,Variables!C11,Variables!D11)) -> 0 | D12: =Summary!D21 -> 0 | E12: =IF(D5=0,"",IF(D12<C12,Variables!E11,Variables!F11))
B13: Sale in Year 5 | C13: =IF($B$46=Variables!$E$27,Variables!C12,IF($B$46=Variables!$F$26,Variables!C12,Variables!D12)) -> Yes | D13: =IF('Exit Strategy'!D5=5,"Yes","No") -> Yes | E13: =IF(D5=0,"",IF(D13=C13,Variables!F12,Variables!E12))
B14: Deal Size | C14: =IF($B$46=Variables!$E$27,Variables!C13,IF($B$46=Variables!$F$26,Variables!C13,Variables!D13)) -> 1000000 | D14: =Summary!D10 -> 0 | E14: =IF($D$5=0,"",IF(D14>=C14,Variables!F13,Variables!E13))
B16: Deal Readiness Questionnaire
B17: Before you make a formal offer (LOI or Contract), complete this questionnaire to make sure the deal is ready. It will ensure that you've researched the deal enough to move forward. If you can't answer these questions thoroughly, you may need to do some more work.
B18: Provide an Executive Summary of This Deal If you had 60 seconds to explain this deal to someone else, what would you say?
B20: What City Is This Property In?
B22: Cleary Describe the PROBLEM with this Property and Your SOLUTION.
B23: If rents are low, why are the low? How do you know (i.e. who did you talk to)? What's the plan to raise rents, and what will it take and how much will it cost to achieve the target rents?
B25: Is the property poorly managed? Why? Is it self-managed or some other reason? What makes you think you can manage it better?
B27: Are there any down units? If so, why are they down? What needs to happen to get them rent-ready?
B29: Are vacancies high? If so, why? How do you know this? What needs to happen to achieve the occupancy targets?
B31: Are the expenses high? If so, why? How do you know this? What is your plan for reducing the expenses?
B33: Provide details about your estimated repairs you provided in the "Summary" tab.
B35: How Did You Arrive at the Market Cap Rate?
... B39: Where Are You With the Negotiation?
B40: Click to Select | D40: =IF(B40=Variables!F20, Variables!F21,IF(B40=Variables!G20,Variables!G21,IF(B40=Variables!H20,Variables!H21,IF(B40=Variables!I20,Variables!I21,IF(B40=Variables!J20,Variables!J21,IF(B40=Variables!K20,Variables!K21,IF(B40=Variables!L20,Variables!L21,"")))))))
B41: Did You Visit the Property?
B42: Click to Select | D42: =IF(B42="Yes", Variables!E24,IF(B42="No",Variables!F23,""))
B43: Have You Spoken To a Mortgage Broker/Lender?
B44: Click to Select | D44: =IF(B44="Yes", Variables!E26,IF(B44="No",Variables!F25,""))
B45: Would You Consider this a "Value-Add" or "Stable" Deal? This slightly changes the Minimum Criteria in the Deal Readiness Dashboard.
B46: Click to Select | D46: =IF(B46="Value-Add", Variables!E28,IF(B46="Stable",Variables!F27,""))
B48: ="Copyright © "&YEAR(TODAY())&" Michael Blank." -> Copyright © 2026 Michael Blank.
B49: The information herein is not guaranteed but believed to be accurate.

Sheet Scenarios
B1: Side-by-Side Scenarios
A2: "The 10 Minute Offer"
D3: 1. Marketing Package | G3: 2. My Version | J3: 3. Projected | M3: 4. Offer | P3: 5. Scenario A | S3: 6. Scenario B | V3: 7. Scenario C | Y3: 8. Scenario D
B5: Acquisition | AC5: Target Rent Analysis
B6: Asking Price | D6: 0 | G6: =D6 -> 0 | J6: =G6 -> 0 | M6: =J6 -> 0 | P6: =M6 -> 0 | S6: =P6 -> 0 | V6: =S6 -> 0 | Y6: =V6 -> 0 | AE6: Current Rent | AG6: Target Rent
B7: Purchase | D7: =D6 -> 0 | G7: =G6 -> 0 | J7: =G7 -> 0 | M7: =J7 -> 0 | P7: =M7 -> 0 | S7: =P7 -> 0 | V7: =S7 -> 0 | Y7: =V7 -> 0 | AC7: Type | AD7: # Units | AE7: Average | AF7: Total | AG7: Average | AH7: Total
B8: # Units | D8: 0 | G8: =D8 -> 0 | J8: =G8 -> 0 | M8: =J8 -> 0 | P8: =M8 -> 0 | S8: =P8 -> 0 | V8: =S8 -> 0 | Y8: =V8 -> 0 | AC8: Unit type | AD8: 0 | AE8: 0 | AF8: =AE8*AD8 -> 0 | AG8: 0 | AH8: =AG8*AD8 -> 0
B9: Price Per Unit | D9: =IF(D8=0,0,D7/D8) -> 0 | G9: =IF(G8=0,0,G7/G8) -> 0 | J9: =IF(J8=0,0,J7/J8) -> 0 | M9: =IF(M8=0,0,M7/M8) -> 0 | P9: =IF(P8=0,0,P7/P8) -> 0 | S9: =IF(S8=0,0,S7/S8) -> 0 | V9: =IF(V8=0,0,V7/V8) -> 0 | Y9: =IF(Y8=0,0,Y7/Y8) -> 0 | AC9: Unit type | AD9: 0 | AE9: 0 | AF9: =AE9*AD9 -> 0 | AG9: 0 | AH9: =AG9*AD9 -> 0
B10: Down payment % | D10: 0.25 | G10: =D10 -> 0.25 | J10: =G10 -> 0.25 | M10: =J10 -> 0.25 | P10: =M10 -> 0.25 | S10: =P10 -> 0.25 | V10: =S10 -> 0.25 | Y10: =V10 -> 0.25 | AC10: Unit type | AD10: 0 | AE10: 0 | AF10: =AE10*AD10 -> 0 | AG10: 0 | AH10: =AG10*AD10 -> 0
B11: Down payment $ | D11: =D10*D7 -> 0 | G11: =G10*G7 -> 0 | J11: =J10*J7 -> 0 | M11: =M10*M7 -> 0 | P11: =P10*P7 -> 0 | S11: =S10*S7 -> 0 | V11: =V10*V7 -> 0 | Y11: =Y10*Y7 -> 0 | AC11: Unit type | AD11: 0 | AE11: 0 | AF11: =AE11*AD11 -> 0 | AG11: 0 | AH11: =AG11*AD11 -> 0
B12: Interest Only (in months) | D12: 0 | G12: =D12 -> 0 | J12: =G12 -> 0 | M12: =J12 -> 0 | P12: =M12 -> 0 | S12: =P12 -> 0 | V12: =S12 -> 0 | Y12: =V12 -> 0 | AC12: Unit type | AD12: 0 | AE12: 0 | AF12: =AE12*AD12 -> 0 | AG12: 0 | AH12: =AG12*AD12 -> 0
B13: Loan Balance | D13: =D7-D11 -> 0 | G13: =G7-G11 -> 0 | J13: =J7-J11 -> 0 | M13: =M7-M11 -> 0 | P13: =P7-P11 -> 0 | S13: =S7-S11 -> 0 | V13: =V7-V11 -> 0 | Y13: =Y7-Y11 -> 0 | AC13: Unit type | AD13: 0 | AE13: 0 | AF13: =AE13*AD13 -> 0 | AG13: 0 | AH13: =AG13*AD13 -> 0
B14: Repairs | C14: OFF | D14: =IF($C$14="OFF",0,Repairs!$E$35) -> 0 | G14: =IF($C$14="OFF",D14,Repairs!$E$35) -> 0 | J14: =IF($C$14="OFF",G14,Repairs!$E$35) -> 0 | M14: =IF($C$14="OFF",J14,Repairs!$E$35) -> 0 | P14: =IF($C$14="OFF",M14,Repairs!$E$35) -> 0 | S14: =IF($C$14="OFF",P14,Repairs!$E$35) -> 0 | V14: =IF($C$14="OFF",S14,Repairs!$E$35) -> 0 | Y14: =IF($C$14="OFF",V14,Repairs!$E$35) -> 0 | AC14: Unit type | AD14: 0 | AE14: 0 | AF14: =AE14*AD14 -> 0 | AG14: 0 | AH14: =AG14*AD14 -> 0
B15: Operating Reserves | D15: 0 | G15: =D15 -> 0 | J15: =G15 -> 0 | M15: =J15 -> 0 | P15: =M15 -> 0 | S15: =P15 -> 0 | V15: =S15 -> 0 | Y15: =V15 -> 0 | AC15: Total / Average | AD15: =SUM(AD8:AD14) -> 0 | AE15: =IF(AD15>0,AF15/AD15,0) -> 0 | AF15: =SUM(AF8:AF14) -> 0 | AG15: =IF(AD15>0,AH15/AD15,0) -> 0 | AH15: =SUM(AH8:AH14) -> 0
B16: Estimated closing costs | D16: =Summary!$D$18 -> 0 | G16: =Summary!$D$18 -> 0 | J16: =Summary!$D$18 -> 0 | M16: =Summary!$D$18 -> 0 | P16: =Summary!$D$18 -> 0 | S16: =Summary!$D$18 -> 0 | V16: =Summary!$D$18 -> 0 | Y16: =Summary!$D$18 -> 0
B17: Total Acquisition Cost | D17: =D14+D7+D16+D15 -> 0 | G17: =G14+G7+G16+G15 -> 0 | J17: =J14+J7+J16+J15 -> 0 | M17: =M14+M7+M16+M15 -> 0 | P17: =P14+P7+P16+P15 -> 0 | S17: =S14+S7+S16+S15 -> 0 | V17: =V14+V7+V16+V15 -> 0 | Y17: =Y14+Y7+Y16+Y15 -> 0
B19: Income
B20: Average Monthly Rent | D20: =IF(D21=0,0,D21/12/D8) -> 0 | G20: =IF(G21=0,0,G21/12/G8) -> 0 | J20: =IF(J21=0,0,J21/12/J8) -> 0 | M20: =IF(M21=0,0,M21/12/M8) -> 0 | P20: =IF(P21=0,0,P21/12/P8) -> 0 | S20: =IF(S21=0,0,S21/12/S8) -> 0 | V20: =IF(V21=0,0,V21/12/V8) -> 0 | Y20: =IF(Y21=0,0,Y21/12/Y8) -> 0
B21: Gross Potential Rent | D21: 0 | G21: =D21 -> 0 | J21: =G21 -> 0 | M21: =J21 -> 0 | P21: =M21 -> 0 | S21: =P21 -> 0 | V21: =S21 -> 0 | Y21: =V21 -> 0 | AB21: =CHOOSE(Summary!$G$3,D21,G21,J21,M21,P21,S21,V21,Y21) -> 0 | AC21: Rules of Thumb
B22: - Vacancy | D22: 0 | F22: =IFERROR(-D22/D21,0) -> 0 | G22: =-I22*G21 -> 0 | I22: 0.1 | J22: =-L22*J21 -> 0 | L22: 0.1 | M22: =-O22*M21 -> 0 | O22: 0.1 | P22: =-R22*P21 -> 0 | R22: 0.1 | S22: =-U22*S21 -> 0 | U22: 0.1 | V22: =-X22*V21 -> 0 | X22: 0.1 | Y22: =-AA22*Y21 -> 0 | AA22: 0.1 | AC22: Sales Price | AD22: =M7 -> 0
B23: - Concessions, Loss to Lease, Bad Debt | D23: 0 | F23: =IFERROR(-D23/D21,0) -> 0 | G23: =-I23*G21 -> 0 | I23: 0.05 | J23: =-L23*J21 -> 0 | L23: 0.05 | M23: =-O23*M21 -> 0 | O23: 0.05 | P23: =-R23*P21 -> 0 | R23: 0.05 | S23: =-U23*S21 -> 0 | U23: 0.05 | V23: =-X23*V21 -> 0 | X23: 0.05 | Y23: =-AA23*Y21 -> 0 | AA23: 0.05 | AC23: # Units | AD23: =M8 -> 0
B24: Gross Potential Income | D24: =D21+D22+D23 -> 0 | G24: =SUM(G21:G23) -> 0 | J24: =SUM(J21:J23) -> 0 | M24: =SUM(M21:M23) -> 0 | P24: =SUM(P21:P23) -> 0 | S24: =SUM(S21:S23) -> 0 | V24: =SUM(V21:V23) -> 0 | Y24: =SUM(Y21:Y23) -> 0 | AC24: Effective Gross Income | AD24: =M26 -> 0
B25: Other Income | D25: 0 | G25: =D25 -> 0 | J25: =G25 -> 0 | M25: =J25 -> 0 | P25: =M25 -> 0 | S25: =P25 -> 0 | V25: =S25 -> 0 | Y25: =V25 -> 0 | AB25: =CHOOSE(Summary!$G$3,D25,G25,J25,M25,P25,S25,V25,Y25) -> 0 | AD25: General Rule of Thumb | AG25: From Appraiser | AI25: Other Properties | AK25: My Rule of Thumb
B26: Effective Gross Income | D26: =D24+D25 -> 0 | G26: =G24+G25 -> 0 | J26: =J24+J25 -> 0 | M26: =M24+M25 -> 0 | P26: =P24+P25 -> 0 | S26: =S24+S25 -> 0 | V26: =V24+V25 -> 0 | Y26: =Y24+Y25 -> 0 | AE26: Per Year | AI26: Property 1 | AJ26: Property 2
AC27: EXPENSES | AD27: Comment | AE27: Per Unit | AF27: Total | AG27: Per Unit | AH27: Total | AI27: Per Unit | AJ27: Per Unit | AK27: Per Year | AL27: Comment
B28: Expenses | E28: Per Unit | H28: Per Unit | K28: Per Unit | N28: Per Unit | Q28: Per Unit | T28: Per Unit | W28: Per Unit | Z28: Per Unit | AC28: Real Estate Taxes | AD28: 1% of Sales Price | AE28: =IFERROR(AF28/$AD$23,0) -> 0 | AF28: =0.01*AD22 -> 0 | AK28: =AF28 -> 0
B29: ='P&L'!B19 -> Advertising | D29: 0 | E29: =IF(D29>0,D29/D$8,0) -> 0 | F29: =IF(D$26=0,0,D29/D$26) -> 0 | G29: =D29 -> 0 | H29: =IF(G29>0,G29/G$8,0) -> 0 | I29: =IF(G$26=0,0,G29/G$26) -> 0 | J29: =G29 -> 0 | K29: =IF(J29>0,J29/J$8,0) -> 0 | L29: =IF(J$26=0,0,J29/J$26) -> 0 | M29: =J29 -> 0 | N29: =IF(M29>0,M29/M$8,0) -> 0 | O29: =IF(M$26=0,0,M29/M$26) -> 0 | P29: =M29 -> 0 | Q29: =IF(P29>0,P29/P$8,0) -> 0 | R29: =IF(P$26=0,0,P29/P$26) -> 0 | S29: =P29 -> 0 | T29: =IF(S29>0,S29/S$8,0) -> 0 | U29: =IF(S$26=0,0,S29/S$26) -> 0 | V29: =S29 -> 0 | W29: =IF(V29>0,V29/V$8,0) -> 0 | X29: =IF(V$26=0,0,V29/V$26) -> 0 | Y29: =V29 -> 0 | Z29: =IF(Y29>0,Y29/Y$8,0) -> 0 | AA29: =IF(Y$26=0,0,Y29/Y$26) -> 0 | AC29: Insurance | AD29: 0.007 of sales price | AE29: 400 | AF29: =0.007*AD22 -> 0 | AG29: 450 | AH29: =AG29*$AD$23 -> 0 | AI29: 267 | AJ29: 332 | AK29: =AF29 -> 0
B30: ='P&L'!B20 -> Contract Services | D30: 0 | E30: =IF(D30>0,D30/D$8,0) -> 0 | F30: =IF($D$26=0,0,D30/D$26) -> 0 | G30: =D30 -> 0 | H30: =IF(G30>0,G30/G$8,0) -> 0 | I30: =IF(G$26=0,0,G30/G$26) -> 0 | J30: =G30 -> 0 | K30: =IF(J30>0,J30/J$8,0) -> 0 | L30: =IF(J$26=0,0,J30/J$26) -> 0 | M30: =J30 -> 0 | N30: =IF(M30>0,M30/M$8,0) -> 0 | O30: =IF(M$26=0,0,M30/M$26) -> 0 | P30: =M30 -> 0 | Q30: =IF(P30>0,P30/P$8,0) -> 0 | R30: =IF(P$26=0,0,P30/P$26) -> 0 | S30: =P30 -> 0 | T30: =IF(S30>0,S30/S$8,0) -> 0 | U30: =IF(S$26=0,0,S30/S$26) -> 0 | V30: =S30 -> 0 | W30: =IF(V30>0,V30/V$8,0) -> 0 | X30: =IF(V$26=0,0,V30/V$26) -> 0 | Y30: =V30 -> 0 | Z30: =IF(Y30>0,Y30/Y$8,0) -> 0 | AA30: =IF(Y$26=0,0,Y30/Y$26) -> 0 | AC30: Contract Services | AD30: $200 per unit per year | AE30: 200 | AF30: =AE30*$AD$23 -> 0 | AK30: =AF30 -> 0
B31: ='P&L'!B21 -> Gas & Electric | D31: 0 | E31: =IF(D31>0,D31/D$8,0) -> 0 | F31: =IF($D$26=0,0,D31/D$26) -> 0 | G31: =D31 -> 0 | H31: =IF(G31>0,G31/G$8,0) -> 0 | I31: =IF(G$26=0,0,G31/G$26) -> 0 | J31: =G31 -> 0 | K31: =IF(J31>0,J31/J$8,0) -> 0 | L31: =IF(J$26=0,0,J31/J$26) -> 0 | M31: =J31 -> 0 | N31: =IF(M31>0,M31/M$8,0) -> 0 | O31: =IF(M$26=0,0,M31/M$26) -> 0 | P31: =M31 -> 0 | Q31: =IF(P31>0,P31/P$8,0) -> 0 | R31: =IF(P$26=0,0,P31/P$26) -> 0 | S31: =P31 -> 0 | T31: =IF(S31>0,S31/S$8,0) -> 0 | U31: =IF(S$26=0,0,S31/S$26) -> 0 | V31: =S31 -> 0 | W31: =IF(V31>0,V31/V$8,0) -> 0 | X31: =IF(V$26=0,0,V31/V$26) -> 0 | Y31: =V31 -> 0 | Z31: =IF(Y31>0,Y31/Y$8,0) -> 0 | AA31: =IF(Y$26=0,0,Y31/Y$26) -> 0 | AC31: Trash Removal | AD31: $200 per unit | AE31: 200 | AF31: =AE31*$AD$23 -> 0 | AG31: 125 | AH31: =AG31*$AD$23 -> 0 | AI31: 229 | AJ31: 199 | AK31: =AF31 -> 0
B32: ='P&L'!B22 -> General/Admin | D32: 0 | E32: =IF(D32>0,D32/D$8,0) -> 0 | F32: =IF($D$26=0,0,D32/D$26) -> 0 | G32: =D32 -> 0 | H32: =IF(G32>0,G32/G$8,0) -> 0 | I32: =IF(G$26=0,0,G32/G$26) -> 0 | J32: =G32 -> 0 | K32: =IF(J32>0,J32/J$8,0) -> 0 | L32: =IF(J$26=0,0,J32/J$26) -> 0 | M32: =J32 -> 0 | N32: =IF(M32>0,M32/M$8,0) -> 0 | O32: =IF(M$26=0,0,M32/M$26) -> 0 | P32: =M32 -> 0 | Q32: =IF(P32>0,P32/P$8,0) -> 0 | R32: =IF(P$26=0,0,P32/P$26) -> 0 | S32: =P32 -> 0 | T32: =IF(S32>0,S32/S$8,0) -> 0 | U32: =IF(S$26=0,0,S32/S$26) -> 0 | V32: =S32 -> 0 | W32: =IF(V32>0,V32/V$8,0) -> 0 | X32: =IF(V$26=0,0,V32/V$26) -> 0 | Y32: =V32 -> 0 | Z32: =IF(Y32>0,Y32/Y$8,0) -> 0 | AA32: =IF(Y$26=0,0,Y32/Y$26) -> 0 | AC32: Electric | AD32: $100/unit for common areas | AE32: 100 | AF32: =AE32*$AD$23 -> 0 | AI32: 100 | AJ32: 111 | AK32: =AF32 -> 0
B33: ='P&L'!B23 -> Insurance | D33: 0 | E33: =IF(D33>0,D33/D$8,0) -> 0 | F33: =IF($D$26=0,0,D33/D$26) -> 0 | G33: =D33 -> 0 | H33: =IF(G33>0,G33/G$8,0) -> 0 | I33: =IF(G$26=0,0,G33/G$26) -> 0 | J33: =G33 -> 0 | K33: =IF(J33>0,J33/J$8,0) -> 0 | L33: =IF(J$26=0,0,J33/J$26) -> 0 | M33: =J33 -> 0 | N33: =IF(M33>0,M33/M$8,0) -> 0 | O33: =IF(M$26=0,0,M33/M$26) -> 0 | P33: =M33 -> 0 | Q33: =IF(P33>0,P33/P$8,0) -> 0 | R33: =IF(P$26=0,0,P33/P$26) -> 0 | S33: =P33 -> 0 | T33: =IF(S33>0,S33/S$8,0) -> 0 | U33: =IF(S$26=0,0,S33/S$26) -> 0 | V33: =S33 -> 0 | W33: =IF(V33>0,V33/V$8,0) -> 0 | X33: =IF(V$26=0,0,V33/V$26) -> 0 | Y33: =V33 -> 0 | Z33: =IF(Y33>0,Y33/Y$8,0) -> 0 | AA33: =IF(Y$26=0,0,Y33/Y$26) -> 0 | AC33: Gas | AD33: If owner pays, $100/unit/month | AE33: 100 | AF33: =AE33*$AD$23*12 -> 0 | AK33: =AF33 -> 0
B34: ='P&L'!B24 -> Legal | D34: 0 | E34: =IF(D34>0,D34/D$8,0) -> 0 | F34: =IF($D$26=0,0,D34/D$26) -> 0 | G34: =D34 -> 0 | H34: =IF(G34>0,G34/G$8,0) -> 0 | I34: =IF(G$26=0,0,G34/G$26) -> 0 | J34: =G34 -> 0 | K34: =IF(J34>0,J34/J$8,0) -> 0 | L34: =IF(J$26=0,0,J34/J$26) -> 0 | M34: =J34 -> 0 | N34: =IF(M34>0,M34/M$8,0) -> 0 | O34: =IF(M$26=0,0,M34/M$26) -> 0 | P34: =M34 -> 0 | Q34: =IF(P34>0,P34/P$8,0) -> 0 | R34: =IF(P$26=0,0,P34/P$26) -> 0 | S34: =P34 -> 0 | T34: =IF(S34>0,S34/S$8,0) -> 0 | U34: =IF(S$26=0,0,S34/S$26) -> 0 | V34: =S34 -> 0 | W34: =IF(V34>0,V34/V$8,0) -> 0 | X34: =IF(V$26=0,0,V34/V$26) -> 0 | Y34: =V34 -> 0 | Z34: =IF(Y34>0,Y34/Y$8,0) -> 0 | AA34: =IF(Y$26=0,0,Y34/Y$26) -> 0 | AC34: Water and Sewer | AD34: $400/unit | AE34: 400 | AF34: =AE34*$AD$23 -> 0 | AG34: 500 | AH34: =AG34*$AD$23 -> 0 | AI34: 500 | AJ34: 607 | AK34: =AF34 -> 0
B35: ='P&L'!B25 -> Real Estate Taxes | D35: 0 | E35: =IF(D35>0,D35/D$8,0) -> 0 | F35: =IF($D$26=0,0,D35/D$26) -> 0 | G35: =D35 -> 0 | H35: =IF(G35>0,G35/G$8,0) -> 0 | I35: =IF(G$26=0,0,G35/G$26) -> 0 | J35: =G35 -> 0 | K35: =IF(J35>0,J35/J$8,0) -> 0 | L35: =IF(J$26=0,0,J35/J$26) -> 0 | M35: =J35 -> 0 | N35: =IF(M35>0,M35/M$8,0) -> 0 | O35: =IF(M$26=0,0,M35/M$26) -> 0 | P35: =M35 -> 0 | Q35: =IF(P35>0,P35/P$8,0) -> 0 | R35: =IF(P$26=0,0,P35/P$26) -> 0 | S35: =P35 -> 0 | T35: =IF(S35>0,S35/S$8,0) -> 0 | U35: =IF(S$26=0,0,S35/S$26) -> 0 | V35: =S35 -> 0 | W35: =IF(V35>0,V35/V$8,0) -> 0 | X35: =IF(V$26=0,0,V35/V$26) -> 0 | Y35: =V35 -> 0 | Z35: =IF(Y35>0,Y35/Y$8,0) -> 0 | AA35: =IF(Y$26=0,0,Y35/Y$26) -> 0 | AC35: Legal Fees | AD35: $150 per unit | AE35: =IFERROR(AF35/$AD$23,0) -> 0 | AF35: =150*AD23 -> 0 | AG35: 150 | AH35: =AG35*$AD$23 -> 0 | AK35: =AF35 -> 0
B36: ='P&L'!B26 -> Trash Removal | D36: 0 | E36: =IF(D36>0,D36/D$8,0) -> 0 | F36: =IF($D$26=0,0,D36/D$26) -> 0 | G36: =D36 -> 0 | H36: =IF(G36>0,G36/G$8,0) -> 0 | I36: =IF(G$26=0,0,G36/G$26) -> 0 | J36: =G36 -> 0 | K36: =IF(J36>0,J36/J$8,0) -> 0 | L36: =IF(J$26=0,0,J36/J$26) -> 0 | M36: =J36 -> 0 | N36: =IF(M36>0,M36/M$8,0) -> 0 | O36: =IF(M$26=0,0,M36/M$26) -> 0 | P36: =M36 -> 0 | Q36: =IF(P36>0,P36/P$8,0) -> 0 | R36: =IF(P$26=0,0,P36/P$26) -> 0 | S36: =P36 -> 0 | T36: =IF(S36>0,S36/S$8,0) -> 0 | U36: =IF(S$26=0,0,S36/S$26) -> 0 | V36: =S36 -> 0 | W36: =IF(V36>0,V36/V$8,0) -> 0 | X36: =IF(V$26=0,0,V36/V$26) -> 0 | Y36: =V36 -> 0 | Z36: =IF(Y36>0,Y36/Y$8,0) -> 0 | AA36: =IF(Y$26=0,0,Y36/Y$26) -> 0 | AC36: Management Fees | AD36: 5-10% of Gross Income | AG36: 0.06 | AK36: =AF36 -> 0
B37: ='P&L'!B27 -> Management Fee | D37: 0 | E37: =IF(D37>0,D37/D$8,0) -> 0 | F37: =IF($D$26=0,0,D37/D$26) -> 0 | G37: =I37*G26 -> 0 | H37: =IF(G37>0,G37/G$8,0) -> 0 | I37: 0 | J37: =L37*J26 -> 0 | K37: =IF(J37>0,J37/J$8,0) -> 0 | L37: =I37 -> 0 | M37: =O37*M26 -> 0 | N37: =IF(M37>0,M37/M$8,0) -> 0 | O37: =L37 -> 0 | P37: =R37*P26 -> 0 | Q37: =IF(P37>0,P37/P$8,0) -> 0 | R37: =O37 -> 0 | S37: =U37*S26 -> 0 | T37: =IF(S37>0,S37/S$8,0) -> 0 | U37: =R37 -> 0 | V37: =X37*V26 -> 0 | W37: =IF(V37>0,V37/V$8,0) -> 0 | X37: =U37 -> 0 | Y37: =AA37*Y26 -> 0 | Z37: =IF(Y37>0,Y37/Y$8,0) -> 0 | AA37: =X37 -> 0 | AC37: Repairs and Maintenance | AD37: 10% of Gross Income | AF37: =0.1*AD24 -> 0 | AG37: 1000 | AH37: =AG37*$AD$23 -> 0 | AK37: =AF37 -> 0
B38: ='P&L'!B28 -> Payroll | D38: 0 | E38: =IF(D38>0,D38/D$8,0) -> 0 | F38: =IF($D$26=0,0,D38/D$26) -> 0 | G38: =D38 -> 0 | H38: =IF(G38>0,G38/G$8,0) -> 0 | I38: =IF(G$26=0,0,G38/G$26) -> 0 | J38: =G38 -> 0 | K38: =IF(J38>0,J38/J$8,0) -> 0 | L38: =IF(J$26=0,0,J38/J$26) -> 0 | M38: =J38 -> 0 | N38: =IF(M38>0,M38/M$8,0) -> 0 | O38: =IF(M$26=0,0,M38/M$26) -> 0 | P38: =M38 -> 0 | Q38: =IF(P38>0,P38/P$8,0) -> 0 | R38: =IF(P$26=0,0,P38/P$26) -> 0 | S38: =P38 -> 0 | T38: =IF(S38>0,S38/S$8,0) -> 0 | U38: =IF(S$26=0,0,S38/S$26) -> 0 | V38: =S38 -> 0 | W38: =IF(V38>0,V38/V$8,0) -> 0 | X38: =IF(V$26=0,0,V38/V$26) -> 0 | Y38: =V38 -> 0 | Z38: =IF(Y38>0,Y38/Y$8,0) -> 0 | AA38: =IF(Y$26=0,0,Y38/Y$26) -> 0 | AC38: Advertising | AD38: Varies | AK38: 1700
B39: ='P&L'!B29 -> Repairs and Maintenance | D39: 0 | E39: =IF(D39>0,D39/D$8,0) -> 0 | F39: =IF($D$26=0,0,D39/D$26) -> 0 | G39: =D39 -> 0 | H39: =IF(G39>0,G39/G$8,0) -> 0 | I39: =IF(G$26=0,0,G39/G$26) -> 0 | J39: =G39 -> 0 | K39: =IF(J39>0,J39/J$8,0) -> 0 | L39: =IF(J$26=0,0,J39/J$26) -> 0 | M39: =J39 -> 0 | N39: =IF(M39>0,M39/M$8,0) -> 0 | O39: =IF(M$26=0,0,M39/M$26) -> 0 | P39: =M39 -> 0 | Q39: =IF(P39>0,P39/P$8,0) -> 0 | R39: =IF(P$26=0,0,P39/P$26) -> 0 | S39: =P39 -> 0 | T39: =IF(S39>0,S39/S$8,0) -> 0 | U39: =IF(S$26=0,0,S39/S$26) -> 0 | V39: =S39 -> 0 | W39: =IF(V39>0,V39/V$8,0) -> 0 | X39: =IF(V$26=0,0,V39/V$26) -> 0 | Y39: =V39 -> 0 | Z39: =IF(Y39>0,Y39/Y$8,0) -> 0 | AA39: =IF(Y$26=0,0,Y39/Y$26) -> 0 | AC39: General/Admin | AD39: Varies | AK39: 1700
B40: ='P&L'!B30 -> Turnover | D40: 0 | E40: =IF(D40>0,D40/D$8,0) -> 0 | F40: =IF($D$26=0,0,D40/D$26) -> 0 | G40: =D40 -> 0 | H40: =IF(G40>0,G40/G$8,0) -> 0 | I40: =IF(G$26=0,0,G40/G$26) -> 0 | J40: =G40 -> 0 | K40: =IF(J40>0,J40/J$8,0) -> 0 | L40: =IF(J$26=0,0,J40/J$26) -> 0 | M40: =J40 -> 0 | N40: =IF(M40>0,M40/M$8,0) -> 0 | O40: =IF(M$26=0,0,M40/M$26) -> 0 | P40: =M40 -> 0 | Q40: =IF(P40>0,P40/P$8,0) -> 0 | R40: =IF(P$26=0,0,P40/P$26) -> 0 | S40: =P40 -> 0 | T40: =IF(S40>0,S40/S$8,0) -> 0 | U40: =IF(S$26=0,0,S40/S$26) -> 0 | V40: =S40 -> 0 | W40: =IF(V40>0,V40/V$8,0) -> 0 | X40: =IF(V$26=0,0,V40/V$26) -> 0 | Y40: =V40 -> 0 | Z40: =IF(Y40>0,Y40/Y$8,0) -> 0 | AA40: =IF(Y$26=0,0,Y40/Y$26) -> 0 | AC40: Payroll | AD40: For every 100 units: 1 FT leasing manager and 1 FT maintenance person; confirm with property manager. | AK40: =AF40 -> 0
B41: ='P&L'!B31 -> Water and Sewer | D41: 0 | E41: =IF(D41>0,D41/D$8,0) -> 0 | F41: =IF($D$26=0,0,D41/D$26) -> 0 | G41: =D41 -> 0 | H41: =IF(G41>0,G41/G$8,0) -> 0 | I41: =IF(G$26=0,0,G41/G$26) -> 0 | J41: =G41 -> 0 | K41: =IF(J41>0,J41/J$8,0) -> 0 | L41: =IF(J$26=0,0,J41/J$26) -> 0 | M41: =J41 -> 0 | N41: =IF(M41>0,M41/M$8,0) -> 0 | O41: =IF(M$26=0,0,M41/M$26) -> 0 | P41: =M41 -> 0 | Q41: =IF(P41>0,P41/P$8,0) -> 0 | R41: =IF(P$26=0,0,P41/P$26) -> 0 | S41: =P41 -> 0 | T41: =IF(S41>0,S41/S$8,0) -> 0 | U41: =IF(S$26=0,0,S41/S$26) -> 0 | V41: =S41 -> 0 | W41: =IF(V41>0,V41/V$8,0) -> 0 | X41: =IF(V$26=0,0,V41/V$26) -> 0 | Y41: =V41 -> 0 | Z41: =IF(Y41>0,Y41/Y$8,0) -> 0 | AA41: =IF(Y$26=0,0,Y41/Y$26) -> 0 | AC41: Turnover | AK41: =AF41 -> 0
B42: ='P&L'!B32 -> Deposit to Replacement Reserve | D42: =IF(SUM(D29:D41)=0,0,D8*AE42) -> 0 | E42: =IF(D42>0,D42/D$8,0) -> 0 | F42: =IF($D$26=0,0,D42/D$26) -> 0 | G42: =D42 -> 0 | H42: =IF(G42>0,G42/G$8,0) -> 0 | I42: =IF(G$26=0,0,G42/G$26) -> 0 | J42: =G42 -> 0 | K42: =IF(J42>0,J42/J$8,0) -> 0 | L42: =IF(J$26=0,0,J42/J$26) -> 0 | M42: =J42 -> 0 | N42: =IF(M42>0,M42/M$8,0) -> 0 | O42: =IF(M$26=0,0,M42/M$26) -> 0 | P42: =M42 -> 0 | Q42: =IF(P42>0,P42/P$8,0) -> 0 | R42: =IF(P$26=0,0,P42/P$26) -> 0 | S42: =P42 -> 0 | T42: =IF(S42>0,S42/S$8,0) -> 0 | U42: =IF(S$26=0,0,S42/S$26) -> 0 | V42: =S42 -> 0 | W42: =IF(V42>0,V42/V$8,0) -> 0 | X42: =IF(V$26=0,0,V42/V$26) -> 0 | Y42: =V42 -> 0 | Z42: =IF(Y42>0,Y42/Y$8,0) -> 0 | AA42: =IF(Y$26=0,0,Y42/Y$26) -> 0 | AC42: Replacement Reserves | AD42: $250 per unit | AE42: 250 | AF42: =AE42*$AD$23 -> 0 | AG42: 250 | AH42: =AG42*$AD$23 -> 0 | AK42: =AF42 -> 0
...

Sheet Summary
B1: Executive Summary
B3: PURCHASE | F3: Populate with scenario # | G3: 1 | I3: 1. Marketing Package
B4: # Units | D4: =CHOOSE(Summary!$G$3,Scenarios!D8,Scenarios!G8,Scenarios!J8,Scenarios!M8,Scenarios!P8,Scenarios!S8,Scenarios!V8,Scenarios!Y8) -> 0 | I4: 2. My Version
B5: Asking Price | D5: =CHOOSE(Summary!$G$3,Scenarios!D6,Scenarios!G6,Scenarios!J6,Scenarios!M6,Scenarios!P6,Scenarios!S6,Scenarios!V6,Scenarios!Y6) -> 0 | I5: 3. Projected
B6: Purchase Price | D6: =CHOOSE(Summary!$G$3,Scenarios!D7,Scenarios!G7,Scenarios!J7,Scenarios!M7,Scenarios!P7,Scenarios!S7,Scenarios!V7,Scenarios!Y7) -> 0 | I6: 4. Offer
B7: Price Per Unit | D7: =IF(D4=0,0,D6/D4) -> 0
B8: Earnest Money Deposit (EMD) | C8: 0.01 | D8: =D6*C8 -> 0
B9: Down Payment | C9: =CHOOSE(Summary!$G$3,Scenarios!D10,Scenarios!G10,Scenarios!J10,Scenarios!M10,Scenarios!P10,Scenarios!S10,Scenarios!V10,Scenarios!Y10) -> 0.25 | D9: =IF(D5=0,0,(IF(Loans!C3="Yes",(SUM(Loans!C7:C9)-Loans!E10),(D6*C9)))) -> 0
B10: 1st Mortgage (for LTC, see "Loans" sheet) | D10: =IF(D5=0,0,(IF(Loans!C3="Yes",Loans!E10,D6-D9))) -> 0 | F10: =About!E14
B11: Interest Rate | D11: =CHOOSE(Summary!$G$3,Scenarios!D53,Scenarios!G53,Scenarios!J53,Scenarios!M53,Scenarios!P53,Scenarios!S53,Scenarios!V53,Scenarios!Y53) -> 0.05
B12: Amortization | D12: =CHOOSE(Summary!$G$3,Scenarios!D54,Scenarios!G54,Scenarios!J54,Scenarios!M54,Scenarios!P54,Scenarios!S54,Scenarios!V54,Scenarios!Y54) -> 30
B13: Interest Only (in months) | D13: =CHOOSE(Summary!$G$3,Scenarios!D12,Scenarios!G12,Scenarios!J12,Scenarios!M12,Scenarios!P12,Scenarios!S12,Scenarios!V12,Scenarios!Y12) -> 0
B14: 2nd Mortgage (or Capital Improvement Funding) | D14: 0
B15: Interest Rate | D15: =IF(D14>0,D11,0) -> 0
B16: Amortization | D16: =IF(D14>0,D12,0) -> 0
B17: Interest Only (in months) | D17: 0
B18: Closing Costs | C18: =IF(D6=0,0,D18/D6) -> 0 | D18: =IF(D6=0,0,'Acquisition Costs'!D51) -> 0
B19: Acquisition Fee | C19: 0.02 | D19: =C19*D6 -> 0
B20: Repairs | D20: =CHOOSE(Summary!$G$3,Scenarios!D14,Scenarios!G14,Scenarios!J14,Scenarios!M14,Scenarios!P14,Scenarios!S14,Scenarios!V14,Scenarios!Y14) -> 0
B21: Operating Reserves | D21: =CHOOSE(Summary!$G$3,Scenarios!D15,Scenarios!G15,Scenarios!J15,Scenarios!M15,Scenarios!P15,Scenarios!S15,Scenarios!V15,Scenarios!Y15) -> 0 | F21: =About!E12
B22: Total Member Capital Needed to Close | D22: =IF(D5=0,0,(IF(Loans!C3="No",D18+D9+D20+D19+D21-D14,Loans!E16+D19+D21))) -> 0
B23: Current Market Cap Rate | D23: =CHOOSE(Summary!$G$3,Scenarios!D60,Scenarios!G60,Scenarios!J60,Scenarios!M60,Scenarios!P60,Scenarios!S60,Scenarios!V60,Scenarios!Y60) -> 0.07
B24: INCOME & EXPENSES (Year 1)
B25: Gross Scheduled Income | D25: ='P&L'!D11 -> 0
B26: Average Monthly Rent | D26: ='P&L'!D10 -> 0
B27: - Vacancy | C27: =CHOOSE(Summary!$G$3,Scenarios!F22,Scenarios!I22,Scenarios!L22,Scenarios!O22,Scenarios!R22,Scenarios!U22,Scenarios!X22,Scenarios!AA22) -> 0 | D27: ='P&L'!D12 -> 0
B28: - Concessions, Loss to Lease, Bad Debt | C28: =CHOOSE(Summary!$G$3,Scenarios!F23,Scenarios!I23,Scenarios!L23,Scenarios!O23,Scenarios!R23,Scenarios!U23,Scenarios!X23,Scenarios!AA23) -> 0 | D28: ='P&L'!D13 -> 0
B29: = Effective Rental Income | D29: ='P&L'!D14 -> 0
B30: + Other Income | D30: ='P&L'!D15 -> 0
B31: Total Net Income | D31: ='P&L'!D16 -> 0
B32: Expenses | C32: ='P&L'!E33 -> 0 | D32: ='P&L'!D33 -> 0 | F32: =About!E8
B33: Net Operating Income | D33: ='P&L'!D35 -> 0
B34: Debt Service | D34: ='P&L'!D40 -> 0
B35: Cash Flow After Debt Service | D35: =D33-D34 -> 0
B36: KEY INDICATORS
B37: Cash-on-Cash Return | D37: =Returns!N18 -> 0 | F37: =About!E10
B38: Debt Coverage Ratio (Year 1) | D38: =IF(D6=0,0,'P&L'!D62) -> 0 | F38: =About!E5
B39: Gross Rent Multiplier | D39: =IF(D25=0,0,D6/D25) -> 0
B40: INVESTOR RETURNS
B41: Member Equity | D41: 0.8
...

Sheet Acquisition Costs
B1: Acquisition Costs
B3: Use of Capital
B4: Purchase Price | D4: =Summary!D6 -> 0
B5: Less Loan Amount | D5: =Summary!D10+Summary!D14 -> 0
B6: Down Payment | D6: =Summary!D9 -> 0
B7: Closing Costs (see below) | D7: =D51 -> 0
B8: Acquisition Fee | D8: =Summary!D19 -> 0
B9: Repairs | D9: =Summary!D20 -> 0
B10: Cash Requirements at Closing / Members Capital | D10: =IF(Loans!C3="No",SUM(D6:D9),Summary!D22) -> 0
B12: Closing Costs and Reimbursable Expenses
B13: Legal Fees (LLC, PPM)* | D13: 0
B14: Property Inspection* | C14: 0 | D14: =C14*Summary!D4 -> 0
B15: Lead Paint Inspection* | C15: 0 | D15: =C15*Summary!D4 -> 0
B17: Lender Fees and 3rd Party Reports
B18: EDR (Environmental) | D18: 0
B19: Appraisal* | D19: 0
B20: Structural Inspection | D20: 0
B21: Lender Legal Fees | D21: 0
B22: Bank Doc Prep Fee | D22: 0
B23: 1st Mortgage Origination Fee | C23: 0 | D23: =C23*Summary!D10 -> 0
B24: 2nd Mortgage Origination Fee | C24: 0 | D24: =C24*Summary!D14 -> 0
B25: Total Lender Fees and Reports | D25: =SUM(D18:D23)+D24 -> 0
B27: Closing Costs
B28: Title Policy | C28: 0 | D28: =C28*D4 -> 0
B29: Survey | D29: 0
B30: Recording | D30: 0
B31: Transfer Taxes | C31: 0 | D31: =C31*D4 -> 0
B32: Title Processing Fee | D32: 0
B33: Title Search | D33: 0
B34: Attorney Fees | D34: 0
B35: Total Closing Costs | D35: =SUM(D28:D34) -> 0
B37: Escrowed at Closing
B38: Lender-held funds | D38: 0
B39: Real Estate Taxes (1) | D39: 0
B40: Insurance | D40: 0
B41: Principal/Interest Escrow
B42: Number of months withheld | C42: 0
B43: Set year-end of P&I escrow return | C43: 0
B44: Total P/I amount (monthly pmnt * months) | D44: ='1st Mortgage 1'!$D$7*$C$42 -> 0
B45: Total Escrows | D45: =SUM(D38:D44) -> 0
...

Sheet P&L
B1: Profit & Loss
B5: FINANCIAL ASSUMPTIONS | D5: Year 1 | F5: Year 2 | H5: Year 3 | J5: Year 4 | L5: Year 5 | N5: Year 6 | P5: Year 7 | R5: Year 8 | T5: Year 9 | V5: Year 10
B6: Annual Income Escalator | D6: 0 | F6: 0.02 | H6: =F6 -> 0.02 | J6: =H6 -> 0.02 | L6: =J6 -> 0.02 | N6: =L6 -> 0.02 | P6: =N6 -> 0.02 | R6: =P6 -> 0.02 | T6: =R6 -> 0.02 | V6: =T6 -> 0.02
B7: Annual Expense Escalator | D7: 0 | F7: 0.02 | H7: =F7 -> 0.02 | J7: =H7 -> 0.02 | L7: =J7 -> 0.02 | N7: =L7 -> 0.02 | P7: =N7 -> 0.02 | R7: =P7 -> 0.02 | T7: =R7 -> 0.02 | V7: =T7 -> 0.02
D8: =IF(D9=year_refi,"REFINANCE!",IF(D9=year_sale,"SALE!","")) | F8: =IF(F9=year_refi,"REFINANCE!",IF(F9=year_sale,"SALE!","")) | H8: =IF(H9=year_refi,"REFINANCE!",IF(H9=year_sale,"SALE!","")) | J8: =IF(J9=year_refi,"REFINANCE!",IF(J9=year_sale,"SALE!","")) | L8: =IF(L9=year_refi,"REFINANCE!",IF(L9=year_sale,"SALE!","")) -> SALE! | N8: =IF(N9=year_refi,"REFINANCE!",IF(N9=year_sale,"SALE!","")) | P8: =IF(P9=year_refi,"REFINANCE!",IF(P9=year_sale,"SALE!","")) | R8: =IF(R9=year_refi,"REFINANCE!",IF(R9=year_sale,"SALE!","")) | T8: =IF(T9=year_refi,"REFINANCE!",IF(T9=year_sale,"SALE!","")) | V8: =IF(V9=year_refi,"REFINANCE!",IF(V9=year_sale,"SALE!",""))
B9: INCOME | D9: 1 | F9: =D9+1 -> 2 | H9: =F9+1 -> 3 | J9: =H9+1 -> 4 | L9: =J9+1 -> 5 | N9: =L9+1 -> 6 | P9: =N9+1 -> 7 | R9: =P9+1 -> 8 | T9: =R9+1 -> 9 | V9: =T9+1 -> 10
C10: Average Monthly Rent | D10: =IF(Summary!$D$4=0,0,Scenarios!AB21/Summary!$D$4/12)*(1+D6) -> 0 | F10: =D10*(1+F6) -> 0 | H10: =F10*(1+H6) -> 0 | J10: =H10*(1+J6) -> 0 | L10: =J10*(1+L6) -> 0 | N10: =L10*(1+N6) -> 0 | P10: =N10*(1+P6) -> 0 | R10: =P10*(1+R6) -> 0 | T10: =R10*(1+T6) -> 0 | V10: =T10*(1+V6) -> 0
B11: Gross Potential Rent | D11: =D10*Summary!$D$4*12 -> 0 | F11: =F10*Summary!$D$4*12 -> 0 | H11: =H10*Summary!$D$4*12 -> 0 | J11: =J10*Summary!$D$4*12 -> 0 | L11: =L10*Summary!$D$4*12 -> 0 | N11: =N10*Summary!$D$4*12 -> 0 | P11: =P10*Summary!$D$4*12 -> 0 | R11: =R10*Summary!$D$4*12 -> 0 | T11: =T10*Summary!$D$4*12 -> 0 | V11: =V10*Summary!$D$4*12 -> 0
B12: - Vacancy | D12: =-E12*D11 -> 0 | E12: =Summary!C27 -> 0 | F12: =-G12*F11 -> 0 | G12: =E12 -> 0 | H12: =-I12*H11 -> 0 | I12: =G12 -> 0 | J12: =-K12*J11 -> 0 | K12: =I12 -> 0 | L12: =-M12*L11 -> 0 | M12: =K12 -> 0 | N12: =-O12*N11 -> 0 | O12: =M12 -> 0 | P12: =-Q12*P11 -> 0 | Q12: =O12 -> 0 | R12: =-S12*R11 -> 0 | S12: =Q12 -> 0 | T12: =-U12*T11 -> 0 | U12: =S12 -> 0 | V12: =-W12*V11 -> 0 | W12: =U12 -> 0
B13: - Concessions, Loss to Lease, Bad Debt | D13: =-E13*D11 -> 0 | E13: =Summary!C28 -> 0 | F13: =-G13*F11 -> 0 | G13: =E13 -> 0 | H13: =-I13*H11 -> 0 | I13: =G13 -> 0 | J13: =-K13*J11 -> 0 | K13: =I13 -> 0 | L13: =-M13*L11 -> 0 | M13: =K13 -> 0 | N13: =-O13*N11 -> 0 | O13: =M13 -> 0 | P13: =-Q13*P11 -> 0 | Q13: =O13 -> 0 | R13: =-S13*R11 -> 0 | S13: =Q13 -> 0 | T13: =-U13*T11 -> 0 | U13: =S13 -> 0 | V13: =-W13*V11 -> 0 | W13: =U13 -> 0
B14: Gross Potential Income | D14: =SUM(D11:D13) -> 0 | F14: =SUM(F11:F13) -> 0 | H14: =SUM(H11:H13) -> 0 | J14: =SUM(J11:J13) -> 0 | L14: =SUM(L11:L13) -> 0 | N14: =SUM(N11:N13) -> 0 | P14: =SUM(P11:P13) -> 0 | R14: =SUM(R11:R13) -> 0 | T14: =SUM(T11:T13) -> 0 | V14: =SUM(V11:V13) -> 0
B15: Other Income | D15: =Scenarios!AB25*(1+D6) -> 0 | F15: =D15*(1+F6) -> 0 | H15: =F15*(1+H6) -> 0 | J15: =H15*(1+J6) -> 0 | L15: =J15*(1+L6) -> 0 | N15: =L15*(1+N6) -> 0 | P15: =N15*(1+P6) -> 0 | R15: =P15*(1+R6) -> 0 | T15: =R15*(1+T6) -> 0 | V15: =T15*(1+V6) -> 0
B16: Effective Gross Income | D16: =SUM(D14:D15) -> 0 | F16: =SUM(F14:F15) -> 0 | H16: =SUM(H14:H15) -> 0 | J16: =SUM(J14:J15) -> 0 | L16: =SUM(L14:L15) -> 0 | N16: =SUM(N14:N15) -> 0 | P16: =SUM(P14:P15) -> 0 | R16: =SUM(R14:R15) -> 0 | T16: =SUM(T14:T15) -> 0 | V16: =SUM(V14:V15) -> 0
B18: EXPENSES
B19: Advertising | D19: =CHOOSE(Summary!$G$3,Scenarios!D29,Scenarios!G29,Scenarios!J29,Scenarios!M29,Scenarios!P29,Scenarios!S29,Scenarios!V29,Scenarios!Y29)*(1+$D$7) -> 0 | E19: =IF(D19=0,0,D19/$D$16) -> 0 | F19: =D19*(1+F$7) -> 0 | G19: =IF(F19=0,0,F19/$F$16) -> 0 | H19: =F19*(1+H$7) -> 0 | I19: =IF(H19=0,0,H19/$H$16) -> 0 | J19: =H19*(1+J$7) -> 0 | K19: =IF(J19=0,0,J19/$J$16) -> 0 | L19: =J19*(1+L$7) -> 0 | M19: =IF(L19=0,0,L19/$L$16) -> 0 | N19: =L19*(1+N$7) -> 0 | O19: =IF(N19=0,0,N19/$N$16) -> 0 | P19: =N19*(1+P$7) -> 0 | Q19: =IF(P19=0,0,P19/$P$16) -> 0 | R19: =P19*(1+R$7) -> 0 | S19: =IF(R19=0,0,R19/$R$16) -> 0 | T19: =R19*(1+T$7) -> 0 | U19: =IF(T19=0,0,T19/$T$16) -> 0 | V19: =T19*(1+V$7) -> 0 | W19: =IF(V19=0,0,V19/$V$16) -> 0
B20: Contract Services | D20: =CHOOSE(Summary!$G$3,Scenarios!D30,Scenarios!G30,Scenarios!J30,Scenarios!M30,Scenarios!P30,Scenarios!S30,Scenarios!V30,Scenarios!Y30)*(1+$D$7) -> 0 | E20: =IF(D20=0,0,D20/$D$16) -> 0 | F20: =D20*(1+F$7) -> 0 | G20: =IF(F20=0,0,F20/$F$16) -> 0 | H20: =F20*(1+H$7) -> 0 | I20: =IF(H20=0,0,H20/$H$16) -> 0 | J20: =H20*(1+J$7) -> 0 | K20: =IF(J20=0,0,J20/$J$16) -> 0 | L20: =J20*(1+L$7) -> 0 | M20: =IF(L20=0,0,L20/$L$16) -> 0 | N20: =L20*(1+N$7) -> 0 | O20: =IF(N20=0,0,N20/$N$16) -> 0 | P20: =N20*(1+P$7) -> 0 | Q20: =IF(P20=0,0,P20/$P$16) -> 0 | R20: =P20*(1+R$7) -> 0 | S20: =IF(R20=0,0,R20/$R$16) -> 0 | T20: =R20*(1+T$7) -> 0 | U20: =IF(T20=0,0,T20/$T$16) -> 0 | V20: =T20*(1+V$7) -> 0 | W20: =IF(V20=0,0,V20/$V$16) -> 0
B21: Gas & Electric | D21: =CHOOSE(Summary!$G$3,Scenarios!D31,Scenarios!G31,Scenarios!J31,Scenarios!M31,Scenarios!P31,Scenarios!S31,Scenarios!V31,Scenarios!Y31)*(1+$D$7) -> 0 | E21: =IF(D21=0,0,D21/$D$16) -> 0 | F21: =D21*(1+F$7) -> 0 | G21: =IF(F21=0,0,F21/$F$16) -> 0 | H21: =F21*(1+H$7) -> 0 | I21: =IF(H21=0,0,H21/$H$16) -> 0 | J21: =H21*(1+J$7) -> 0 | K21: =IF(J21=0,0,J21/$J$16) -> 0 | L21: =J21*(1+L$7) -> 0 | M21: =IF(L21=0,0,L21/$L$16) -> 0 | N21: =L21*(1+N$7) -> 0 | O21: =IF(N21=0,0,N21/$N$16) -> 0 | P21: =N21*(1+P$7) -> 0 | Q21: =IF(P21=0,0,P21/$P$16) -> 0 | R21: =P21*(1+R$7) -> 0 | S21: =IF(R21=0,0,R21/$R$16) -> 0 | T21: =R21*(1+T$7) -> 0 | U21: =IF(T21=0,0,T21/$T$16) -> 0 | V21: =T21*(1+V$7) -> 0 | W21: =IF(V21=0,0,V21/$V$16) -> 0
B22: General/Admin | D22: =CHOOSE(Summary!$G$3,Scenarios!D32,Scenarios!G32,Scenarios!J32,Scenarios!M32,Scenarios!P32,Scenarios!S32,Scenarios!V32,Scenarios!Y32)*(1+$D$7) -> 0 | E22: =IF(D22=0,0,D22/$D$16) -> 0 | F22: =D22*(1+F$7) -> 0 | G22: =IF(F22=0,0,F22/$F$16) -> 0 | H22: =F22*(1+H$7) -> 0 | I22: =IF(H22=0,0,H22/$H$16) -> 0 | J22: =H22*(1+J$7) -> 0 | K22: =IF(J22=0,0,J22/$J$16) -> 0 | L22: =J22*(1+L$7) -> 0 | M22: =IF(L22=0,0,L22/$L$16) -> 0 | N22: =L22*(1+N$7) -> 0 | O22: =IF(N22=0,0,N22/$N$16) -> 0 | P22: =N22*(1+P$7) -> 0 | Q22: =IF(P22=0,0,P22/$P$16) -> 0 | R22: =P22*(1+R$7) -> 0 | S22: =IF(R22=0,0,R22/$R$16) -> 0 | T22: =R22*(1+T$7) -> 0 | U22: =IF(T22=0,0,T22/$T$16) -> 0 | V22: =T22*(1+V$7) -> 0 | W22: =IF(V22=0,0,V22/$V$16) -> 0
B23: Insurance | D23: =CHOOSE(Summary!$G$3,Scenarios!D33,Scenarios!G33,Scenarios!J33,Scenarios!M33,Scenarios!P33,Scenarios!S33,Scenarios!V33,Scenarios!Y33)*(1+$D$7) -> 0 | E23: =IF(D23=0,0,D23/$D$16) -> 0 | F23: =D23*(1+F$7) -> 0 | G23: =IF(F23=0,0,F23/$F$16) -> 0 | H23: =F23*(1+H$7) -> 0 | I23: =IF(H23=0,0,H23/$H$16) -> 0 | J23: =H23*(1+J$7) -> 0 | K23: =IF(J23=0,0,J23/$J$16) -> 0 | L23: =J23*(1+L$7) -> 0 | M23: =IF(L23=0,0,L23/$L$16) -> 0 | N23: =L23*(1+N$7) -> 0 | O23: =IF(N23=0,0,N23/$N$16) -> 0 | P23: =N23*(1+P$7) -> 0 | Q23: =IF(P23=0,0,P23/$P$16) -> 0 | R23: =P23*(1+R$7) -> 0 | S23: =IF(R23=0,0,R23/$R$16) -> 0 | T23: =R23*(1+T$7) -> 0 | U23: =IF(T23=0,0,T23/$T$16) -> 0 | V23: =T23*(1+V$7) -> 0 | W23: =IF(V23=0,0,V23/$V$16) -> 0
B24: Legal | D24: =CHOOSE(Summary!$G$3,Scenarios!D34,Scenarios!G34,Scenarios!J34,Scenarios!M34,Scenarios!P34,Scenarios!S34,Scenarios!V34,Scenarios!Y34)*(1+$D$7) -> 0 | E24: =IF(D24=0,0,D24/$D$16) -> 0 | F24: =D24*(1+F$7) -> 0 | G24: =IF(F24=0,0,F24/$F$16) -> 0 | H24: =F24*(1+H$7) -> 0 | I24: =IF(H24=0,0,H24/$H$16) -> 0 | J24: =H24*(1+J$7) -> 0 | K24: =IF(J24=0,0,J24/$J$16) -> 0 | L24: =J24*(1+L$7) -> 0 | M24: =IF(L24=0,0,L24/$L$16) -> 0 | N24: =L24*(1+N$7) -> 0 | O24: =IF(N24=0,0,N24/$N$16) -> 0 | P24: =N24*(1+P$7) -> 0 | Q24: =IF(P24=0,0,P24/$P$16) -> 0 | R24: =P24*(1+R$7) -> 0 | S24: =IF(R24=0,0,R24/$R$16) -> 0 | T24: =R24*(1+T$7) -> 0 | U24: =IF(T24=0,0,T24/$T$16) -> 0 | V24: =T24*(1+V$7) -> 0 | W24: =IF(V24=0,0,V24/$V$16) -> 0
B25: Real Estate Taxes | D25: =CHOOSE(Summary!$G$3,Scenarios!D35,Scenarios!G35,Scenarios!J35,Scenarios!M35,Scenarios!P35,Scenarios!S35,Scenarios!V35,Scenarios!Y35)*(1+$D$7) -> 0 | E25: =IF(D25=0,0,D25/$D$16) -> 0 | F25: =D25*(1+F$7) -> 0 | G25: =IF(F25=0,0,F25/$F$16) -> 0 | H25: =F25*(1+H$7) -> 0 | I25: =IF(H25=0,0,H25/$H$16) -> 0 | J25: =H25*(1+J$7) -> 0 | K25: =IF(J25=0,0,J25/$J$16) -> 0 | L25: =J25*(1+L$7) -> 0 | M25: =IF(L25=0,0,L25/$L$16) -> 0 | N25: =L25*(1+N$7) -> 0 | O25: =IF(N25=0,0,N25/$N$16) -> 0 | P25: =N25*(1+P$7) -> 0 | Q25: =IF(P25=0,0,P25/$P$16) -> 0 | R25: =P25*(1+R$7) -> 0 | S25: =IF(R25=0,0,R25/$R$16) -> 0 | T25: =R25*(1+T$7) -> 0 | U25: =IF(T25=0,0,T25/$T$16) -> 0 | V25: =T25*(1+V$7) -> 0 | W25: =IF(V25=0,0,V25/$V$16) -> 0
B26: Trash Removal | D26: =CHOOSE(Summary!$G$3,Scenarios!D36,Scenarios!G36,Scenarios!J36,Scenarios!M36,Scenarios!P36,Scenarios!S36,Scenarios!V36,Scenarios!Y36)*(1+$D$7) -> 0 | E26: =IF(D26=0,0,D26/$D$16) -> 0 | F26: =D26*(1+F$7) -> 0 | G26: =IF(F26=0,0,F26/$F$16) -> 0 | H26: =F26*(1+H$7) -> 0 | I26: =IF(H26=0,0,H26/$H$16) -> 0 | J26: =H26*(1+J$7) -> 0 | K26: =IF(J26=0,0,J26/$J$16) -> 0 | L26: =J26*(1+L$7) -> 0 | M26: =IF(L26=0,0,L26/$L$16) -> 0 | N26: =L26*(1+N$7) -> 0 | O26: =IF(N26=0,0,N26/$N$16) -> 0 | P26: =N26*(1+P$7) -> 0 | Q26: =IF(P26=0,0,P26/$P$16) -> 0 | R26: =P26*(1+R$7) -> 0 | S26: =IF(R26=0,0,R26/$R$16) -> 0 | T26: =R26*(1+T$7) -> 0 | U26: =IF(T26=0,0,T26/$T$16) -> 0 | V26: =T26*(1+V$7) -> 0 | W26: =IF(V26=0,0,V26/$V$16) -> 0
B27: Management Fee | D27: =E27*D16 -> 0 | E27: =CHOOSE(Summary!$G$3,Scenarios!F37,Scenarios!I37,Scenarios!L37,Scenarios!O37,Scenarios!R37,Scenarios!U37,Scenarios!X37,Scenarios!AA37) -> 0 | F27: =G27*F16 -> 0 | G27: =E27 -> 0 | H27: =I27*H16 -> 0 | I27: =G27 -> 0 | J27: =K27*J16 -> 0 | K27: =I27 -> 0 | L27: =M27*L16 -> 0 | M27: =K27 -> 0 | N27: =O27*N16 -> 0 | O27: =M27 -> 0 | P27: =Q27*P16 -> 0 | Q27: =O27 -> 0 | R27: =S27*R16 -> 0 | S27: =Q27 -> 0 | T27: =U27*T16 -> 0 | U27: =S27 -> 0 | V27: =W27*V16 -> 0 | W27: =U27 -> 0
B28: Payroll | D28: =CHOOSE(Summary!$G$3,Scenarios!D38,Scenarios!G38,Scenarios!J38,Scenarios!M38,Scenarios!P38,Scenarios!S38,Scenarios!V38,Scenarios!Y38)*(1+$D$7) -> 0 | E28: =IF(D28=0,0,D28/$D$16) -> 0 | F28: =D28*(1+F$7) -> 0 | G28: =IF(F28=0,0,F28/$F$16) -> 0 | H28: =F28*(1+H$7) -> 0 | I28: =IF(H28=0,0,H28/$H$16) -> 0 | J28: =H28*(1+J$7) -> 0 | K28: =IF(J28=0,0,J28/$J$16) -> 0 | L28: =J28*(1+L$7) -> 0 | M28: =IF(L28=0,0,L28/$L$16) -> 0 | N28: =L28*(1+N$7) -> 0 | O28: =IF(N28=0,0,N28/$N$16) -> 0 | P28: =N28*(1+P$7) -> 0 | Q28: =IF(P28=0,0,P28/$P$16) -> 0 | R28: =P28*(1+R$7) -> 0 | S28: =IF(R28=0,0,R28/$R$16) -> 0 | T28: =R28*(1+T$7) -> 0 | U28: =IF(T28=0,0,T28/$T$16) -> 0 | V28: =T28*(1+V$7) -> 0 | W28: =IF(V28=0,0,V28/$V$16) -> 0
B29: Repairs and Maintenance | D29: =CHOOSE(Summary!$G$3,Scenarios!D39,Scenarios!G39,Scenarios!J39,Scenarios!M39,Scenarios!P39,Scenarios!S39,Scenarios!V39,Scenarios!Y39)*(1+$D$7) -> 0 | E29: =IF(D29=0,0,D29/$D$16) -> 0 | F29: =D29*(1+F$7) -> 0 | G29: =IF(F29=0,0,F29/$F$16) -> 0 | H29: =F29*(1+H$7) -> 0 | I29: =IF(H29=0,0,H29/$H$16) -> 0 | J29: =H29*(1+J$7) -> 0 | K29: =IF(J29=0,0,J29/$J$16) -> 0 | L29: =J29*(1+L$7) -> 0 | M29: =IF(L29=0,0,L29/$L$16) -> 0 | N29: =L29*(1+N$7) -> 0 | O29: =IF(N29=0,0,N29/$N$16) -> 0 | P29: =N29*(1+P$7) -> 0 | Q29: =IF(P29=0,0,P29/$P$16) -> 0 | R29: =P29*(1+R$7) -> 0 | S29: =IF(R29=0,0,R29/$R$16) -> 0 | T29: =R29*(1+T$7) -> 0 | U29: =IF(T29=0,0,T29/$T$16) -> 0 | V29: =T29*(1+V$7) -> 0 | W29: =IF(V29=0,0,V29/$V$16) -> 0
B30: Turnover | D30: =CHOOSE(Summary!$G$3,Scenarios!D40,Scenarios!G40,Scenarios!J40,Scenarios!M40,Scenarios!P40,Scenarios!S40,Scenarios!V40,Scenarios!Y40)*(1+$D$7) -> 0 | E30: =IF(D30=0,0,D30/$D$16) -> 0 | F30: =D30*(1+F$7) -> 0 | G30: =IF(F30=0,0,F30/$F$16) -> 0 | H30: =F30*(1+H$7) -> 0 | I30: =IF(H30=0,0,H30/$H$16) -> 0 | J30: =H30*(1+J$7) -> 0 | K30: =IF(J30=0,0,J30/$J$16) -> 0 | L30: =J30*(1+L$7) -> 0 | M30: =IF(L30=0,0,L30/$L$16) -> 0 | N30: =L30*(1+N$7) -> 0 | O30: =IF(N30=0,0,N30/$N$16) -> 0 | P30: =N30*(1+P$7) -> 0 | Q30: =IF(P30=0,0,P30/$P$16) -> 0 | R30: =P30*(1+R$7) -> 0 | S30: =IF(R30=0,0,R30/$R$16) -> 0 | T30: =R30*(1+T$7) -> 0 | U30: =IF(T30=0,0,T30/$T$16) -> 0 | V30: =T30*(1+V$7) -> 0 | W30: =IF(V30=0,0,V30/$V$16) -> 0
B31: Water and Sewer | D31: =CHOOSE(Summary!$G$3,Scenarios!D41,Scenarios!G41,Scenarios!J41,Scenarios!M41,Scenarios!P41,Scenarios!S41,Scenarios!V41,Scenarios!Y41)*(1+$D$7) -> 0 | E31: =IF(D31=0,0,D31/$D$16) -> 0 | F31: =D31*(1+F$7) -> 0 | G31: =IF(F31=0,0,F31/$F$16) -> 0 | H31: =F31*(1+H$7) -> 0 | I31: =IF(H31=0,0,H31/$H$16) -> 0 | J31: =H31*(1+J$7) -> 0 | K31: =IF(J31=0,0,J31/$J$16) -> 0 | L31: =J31*(1+L$7) -> 0 | M31: =IF(L31=0,0,L31/$L$16) -> 0 | N31: =L31*(1+N$7) -> 0 | O31: =IF(N31=0,0,N31/$N$16) -> 0 | P31: =N31*(1+P$7) -> 0 | Q31: =IF(P31=0,0,P31/$P$16) -> 0 | R31: =P31*(1+R$7) -> 0 | S31: =IF(R31=0,0,R31/$R$16) -> 0 | T31: =R31*(1+T$7) -> 0 | U31: =IF(T31=0,0,T31/$T$16) -> 0 | V31: =T31*(1+V$7) -> 0 | W31: =IF(V31=0,0,V31/$V$16) -> 0
B32: Deposit to Replacement Reserve | D32: =CHOOSE(Summary!$G$3,Scenarios!D42,Scenarios!G42,Scenarios!J42,Scenarios!M42,Scenarios!P42,Scenarios!S42,Scenarios!V42,Scenarios!Y42) -> 0 | E32: =IF(D32=0,0,D32/$D$16) -> 0 | F32: =D32 -> 0 | G32: =IF(F32=0,0,F32/$F$16) -> 0 | H32: =F32 -> 0 | I32: =IF(H32=0,0,H32/$H$16) -> 0 | J32: =H32 -> 0 | K32: =IF(J32=0,0,J32/$J$16) -> 0 | L32: =J32 -> 0 | M32: =IF(L32=0,0,L32/$L$16) -> 0 | N32: =L32 -> 0 | O32: =IF(N32=0,0,N32/$N$16) -> 0 | P32: =N32 -> 0 | Q32: =IF(P32=0,0,P32/$P$16) -> 0 | R32: =P32 -> 0 | S32: =IF(R32=0,0,R32/$R$16) -> 0 | T32: =R32 -> 0 | U32: =IF(T32=0,0,T32/$T$16) -> 0 | V32: =T32 -> 0 | W32: =IF(V32=0,0,V32/$V$16) -> 0
B33: Total Expenses | D33: =IF(SUM(D19:D32)=0,Scenarios!AB47*(1+D7),SUM(D19:D32)) -> 0 | E33: =IF(D33=0,0,D33/D16) -> 0 | F33: =IF(SUM(F19:F32)=0,D33*(1+F7),SUM(F19:F32)) -> 0 | G33: =IF(F33=0,0,F33/F16) -> 0 | H33: =IF(SUM(H19:H32)=0,F33*(1+H7),SUM(H19:H32)) -> 0 | I33: =IF(H33=0,0,H33/H16) -> 0 | J33: =IF(SUM(J19:J32)=0,H33*(1+J7),SUM(J19:J32)) -> 0 | K33: =IF(J33=0,0,J33/J16) -> 0 | L33: =IF(SUM(L19:L32)=0,J33*(1+L7),SUM(L19:L32)) -> 0 | M33: =IF(L33=0,0,L33/L16) -> 0 | N33: =IF(SUM(N19:N32)=0,L33*(1+N7),SUM(N19:N32)) -> 0 | O33: =IF(N33=0,0,N33/N16) -> 0 | P33: =IF(SUM(P19:P32)=0,N33*(1+P7),SUM(P19:P32)) -> 0 | Q33: =IF(P33=0,0,P33/P16) -> 0 | R33: =IF(SUM(R19:R32)=0,P33*(1+R7),SUM(R19:R32)) -> 0 | S33: =IF(R33=0,0,R33/R16) -> 0 | T33: =IF(SUM(T19:T32)=0,R33*(1+T7),SUM(T19:T32)) -> 0 | U33: =IF(T33=0,0,T33/T16) -> 0 | V33: =IF(SUM(V19:V32)=0,T33*(1+V7),SUM(V19:V32)) -> 0 | W33: =IF(V33=0,0,V33/V16) -> 0
B35: Net Operating Income (NOI) | D35: =D16-D33 -> 0 | F35: =F16-F33 -> 0 | H35: =H16-H33 -> 0 | J35: =J16-J33 -> 0 | L35: =L16-L33 -> 0 | N35: =N16-N33 -> 0 | P35: =P16-P33 -> 0 | R35: =R16-R33 -> 0 | T35: =T16-T33 -> 0 | V35: =V16-V33 -> 0
B37: Debt Service
B38: Principal | D38: =OFFSET(Loans!$H$32,0,(D9-1)) -> 0 | F38: =OFFSET(Loans!$H$32,0,(F9-1)) -> 0 | H38: =OFFSET(Loans!$H$32,0,(H9-1)) -> 0 | J38: =OFFSET(Loans!$H$32,0,(J9-1)) -> 0 | L38: =OFFSET(Loans!$H$32,0,(L9-1)) -> 0 | N38: =OFFSET(Loans!$H$32,0,(N9-1)) -> 0 | P38: =OFFSET(Loans!$H$32,0,(P9-1)) -> 0 | R38: =OFFSET(Loans!$H$32,0,(R9-1)) -> 0 | T38: =OFFSET(Loans!$H$32,0,(T9-1)) -> 0 | V38: =OFFSET(Loans!$H$32,0,(V9-1)) -> 0
B39: Interest | D39: =OFFSET(Loans!$H$30,0,(D9-1)) -> 0 | F39: =OFFSET(Loans!$H$30,0,(F9-1)) -> 0 | H39: =OFFSET(Loans!$H$30,0,(H9-1)) -> 0 | J39: =OFFSET(Loans!$H$30,0,(J9-1)) -> 0 | L39: =OFFSET(Loans!$H$30,0,(L9-1)) -> 0 | N39: =OFFSET(Loans!$H$30,0,(N9-1)) -> 0 | P39: =OFFSET(Loans!$H$30,0,(P9-1)) -> 0 | R39: =OFFSET(Loans!$H$30,0,(R9-1)) -> 0 | T39: =OFFSET(Loans!$H$30,0,(T9-1)) -> 0 | V39: =OFFSET(Loans!$H$30,0,(V9-1)) -> 0
B40: Total Debt Service | D40: =SUM(D38:D39) -> 0 | F40: =SUM(F38:F39) -> 0 | H40: =SUM(H38:H39) -> 0 | J40: =SUM(J38:J39) -> 0 | L40: =SUM(L38:L39) -> 0 | N40: =SUM(N38:N39) -> 0 | P40: =SUM(P38:P39) -> 0 | R40: =SUM(R38:R39) -> 0 | T40: =SUM(T38:T39) -> 0 | V40: =SUM(V38:V39) -> 0
B42: Cash Flow available for Distribution | D42: =D35-D40 -> 0 | F42: =F35-F40 -> 0 | H42: =H35-H40 -> 0 | J42: =J35-J40 -> 0 | L42: =L35-L40 -> 0 | N42: =N35-N40 -> 0 | P42: =P35-P40 -> 0 | R42: =R35-R40 -> 0 | T42: =T35-T40 -> 0 | V42: =V35-V40 -> 0
B44: Distributions from Cash Flow
B45: Asset Mgt Fee | C45: =Summary!D44 -> 0 | D45: =IF(D9<=year_sale,IF($C$45*D$16<D$42,$C$45*D$16,0),0) -> 0 | F45: =IF(F9<=year_sale,IF($C$45*F$16<F$42,$C$45*F$16,0),0) -> 0 | H45: =IF(H9<=year_sale,IF($C$45*H$16<H$42,$C$45*H$16,0),0) -> 0 | J45: =IF(J9<=year_sale,IF($C$45*J$16<J$42,$C$45*J$16,0),0) -> 0 | L45: =IF(L9<=year_sale,IF($C$45*L$16<L$42,$C$45*L$16,0),0) -> 0 | N45: =IF(N9<=year_sale,IF($C$45*N$16<N$42,$C$45*N$16,0),0) -> 0 | P45: =IF(P9<=year_sale,IF($C$45*P$16<P$42,$C$45*P$16,0),0) -> 0 | R45: =IF(R9<=year_sale,IF($C$45*R$16<R$42,$C$45*R$16,0),0) -> 0 | T45: =IF(T9<=year_sale,IF($C$45*T$16<T$42,$C$45*T$16,0),0) -> 0 | V45: =IF(V9<=year_sale,IF($C$45*V$16<V$42,$C$45*V$16,0),0) -> 0
B46: Members Preferred Return Due | D46: =IF(D53=0,0,D$53*$C$48) -> 0 | F46: =IF(F53=0,0,F$53*$C$48+D$47) -> 0 | H46: =IF(H53=0,0,H$53*$C$48+F$47) -> 0 | J46: =IF(J53=0,0,J$53*$C$48+H$47) -> 0 | L46: =IF(L53=0,0,L$53*$C$48+J$47) -> 0 | N46: =IF(N53=0,0,N$53*$C$48+L$47) -> 0 | P46: =IF(P53=0,0,P$53*$C$48+N$47) -> 0 | R46: =IF(R53=0,0,R$53*$C$48+P$47) -> 0 | T46: =IF(T53=0,0,T$53*$C$48+R$47) -> 0 | V46: =IF(V53=0,0,V$53*$C$48+T$47) -> 0
B47: Members Preferred Return Deficiency | D47: =IF(D$46 >0,D$46-D$48,0) -> 0 | F47: =IF(F$46 >0,F$46-F$48,0) -> 0 | H47: =IF(H$46 >0,H$46-H$48,0) -> 0 | J47: =IF(J$46 >0,J$46-J$48,0) -> 0 | L47: =IF(L$46 >0,L$46-L$48,0) -> 0 | N47: =IF(N$46 >0,N$46-N$48,0) -> 0 | P47: =IF(P$46 >0,P$46-P$48,0) -> 0 | R47: =IF(R$46 >0,R$46-R$48,0) -> 0 | T47: =IF(T$46 >0,T$46-T$48,0) -> 0 | V47: =IF(V$46 >0,V$46-V$48,0) -> 0
B48: Members Preferred Return Paid | C48: =Summary!D43 -> 0 | D48: =IF(D$42>0,IF(D$46+D$45>D$42,D$42-D$45,D$46),0) -> 0 | F48: =IF(F$42>0,IF(F$46+F$45>F$42,F$42-F$45,F$46),0) -> 0 | H48: =IF(H$42>0,IF(H$46+H$45>H$42,H$42-H$45,H$46),0) -> 0 | J48: =IF(J$42>0,IF(J$46+J$45>J$42,J$42-J$45,J$46),0) -> 0 | L48: =IF(L$42>0,IF(L$46+L$45>L$42,L$42-L$45,L$46),0) -> 0 | N48: =IF(N$42>0,IF(N$46+N$45>N$42,N$42-N$45,N$46),0) -> 0 | P48: =IF(P$42>0,IF(P$46+P$45>P$42,P$42-P$45,P$46),0) -> 0 | R48: =IF(R$42>0,IF(R$46+R$45>R$42,R$42-R$45,R$46),0) -> 0 | T48: =IF(T$42>0,IF(T$46+T$45>T$42,T$42-T$45,T$46),0) -> 0 | V48: =IF(V$42>0,IF(V$46+V$45>V$42,V$42-V$45,V$46),0) -> 0
...

Sheet Exit Strategy
B1: Exit Strategy
B3: Exit Strategy | D3: Year
B4: Cash Out Re-Finance at end of year | D4: NA
B5: Sale / Disposition at end of year | D5: 5
B7: Refinance | D7: =year_refi -> NA | F7: Sale | H7: =year_sale -> 5
B8: Net Operating Income | D8: =IF($D$4="NA",0,OFFSET('P&L'!D35,0,$D$4*2-2)+OFFSET('P&L'!D32,0,$D$4*2-2)) -> 0 | F8: Net Operating Income | H8: =OFFSET('P&L'!D35,0,$D$5*2-2)+OFFSET('P&L'!D32,0,$D$5*2-2) -> 0
B9: Cap Rate at Re-Finance | D9: =IF($D$4="NA",0,Summary!$D$23+(var_capRateBump*$D$4)) -> 0 | F9: Cap Rate | H9: =Summary!$D$23+(var_capRateBump*$D$5) -> 0.075 | I9: 0.001 | J9: Cap rate increase per year
B10: Appraised Value | D10: =IF($D$4="NA",0,D8/D9) -> 0 | F10: Insurance/Tax/Lender Escrows | H10: =SUM('Acquisition Costs'!D38:D40) -> 0
B11: Re-Finance LTV | D11: 0.65 | F11: Operating Reserves remaining | H11: =Summary!$D$21*$I$11 -> 0 | I11: 0.5 | J11: % of remaining funds in the operating account at sale
B12: Interest Rate | D12: =IF($D$4="NA",0,Summary!D11) -> 0 | F12: Sales Price | H12: =H8/H9 -> 0
B13: Term / Amortization (Years) | D13: 25 | F13: Sales Cost | G13: =IF(H12<2000000,4%,3%) -> 0.04 | H13: =-G13*H12 -> 0
B14: Interest Only (in months) | D14: 0 | F14: Outstanding Loan Balance | H14: =-OFFSET(Loans!$H$35,0,$D$5-1) -> 0
B15: Re-Finance Loan Amount | D15: =IF($D$4="NA",0,D11*D10) -> 0 | F15: Prepayment penalty | G15: 0 | H15: =H14*G15 -> 0
B16: - Re-Finance Costs | C16: 0.01 | D16: =IF($D$4="NA",0,-C16*D15) -> 0 | F16: Capital Transaction Fee to Mgr | G16: =Summary!D45 -> 0 | H16: =H12*G16 -> 0
B17: - Prepayment Penalty | D17: 0 | F17: Total Equity | H17: =H12+H13+H14+H15-H16+H10+H11 -> 0
B18: - Repay Outstanding Loan Balance | D18: =IF($D$4="NA",0,-OFFSET(Loans!H35,0,$D$4-1)) -> 0 | F18: - Return of Member Capital | H18: =MIN(INDEX(Returns!C5:L5,1,year_sale)-INDEX(Returns!C12:L12,1,year_sale),H17) -> 0
B19: Gross Proceeds from Re-Finance | D19: =IF($D$4="NA",0,SUM(D15:D18)) -> 0 | F19: - Members Preferred Return Deficiency | H19: =MIN(H17-H18,INDEX('P&L'!$D$47:$V$47,1,(year_sale*2)-1)) -> 0
B20: - Capital Transaction Fee to Mgr | C20: 0 | D20: =IF(C20>0,MIN(D15*C20,D19),0) -> 0 | F20: Net Proceeds/Profit from Sale | H20: =H17-H18-H19 -> 0
B21: - Return of Member Capital | D21: =IF($D$4="NA",0,MIN(D19-D20,INDEX(Returns!C5:L5,1,year_refi)-INDEX(Returns!C12:L12,1,year_refi))) -> 0 | F21: Principal Reduction | H21: =OFFSET(Loans!H33,0,$D$5-1)-D25 -> 0
B22: Capital Account Balance After Re-Fi | D22: =IF($D$4="NA",0,INDEX(Returns!C5:L5,1,year_refi)-D21) -> 0 | F22: Appreciation | H22: =IF(H20<=H21,0,H20-H21) -> 0
B23: % of Initial Investment Returned | D23: =IF($D$4="NA",0,1-(D22/Summary!D22)) -> 0 | F23: Net Proceeds/Profit Paid to Members | G23: =Summary!D41 -> 0.8 | H23: =H20*$G$23 -> 0
B24: Net Proceeds/Profit from Re-Finance | D24: =D19-D20-D21 -> 0 | F24: Net Proceeds/Profit Paid to Manager | G24: =Summary!D42 -> 0.2 | H24: =H20*$G$24 -> 0
B25: Principal Reduction | D25: =IF($D$4="NA",0,OFFSET(Loans!H33,0,$D$4-1)) -> 0 | F25: Total Cash to Members at Sale (Init. Cptl. + Apprec.) | H25: =H23+H18+H19 -> 0
B26: Appreciation | D26: =IF($D$4="NA",0,IF(D24=0,0,IF(D24-D25>0,D24-D25,0))) -> 0
B27: Net Proceeds/Profit Paid to Members | C27: =Summary!D41 -> 0.8 | D27: =D24*C27 -> 0 | F27: After Final Disposition
B28: Net Proceeds/Profit Paid to Manager | C28: =Summary!D42 -> 0.2 | D28: =D24*C28 -> 0 | F28: Total Profits from Appreciation Paid to Members | H28: =D27+H23 -> 0
B29: Total Cash to Members at Refi (Init. Cptl. + Apprec.) | D29: =IF($D$4="NA",0,D27+D21) -> 0 | F29: Total Cash to Members | H29: =D29+H25 -> 0
B30: Ending Capital Account Balance | D30: =IF($D$4="NA","",D22) | F30: Internal Rate of Return (IRR) | H30: =Summary!D50 -> 0 | I30: =About!E7
F31: Cash-on-Cash Return | H31: =Summary!D37 -> 0 | I31: =About!E10
B32: =copyright -> Copyright © 2026 Michael Blank.
B33: The information herein is not guaranteed but believed to be accurate.

Sheet Returns
B1: Projected Returns
C3: =IF(C4=year_refi,"REFINANCE!",IF(C4=year_sale,"SALE!","")) | D3: =IF(D4=year_refi,"REFINANCE!",IF(D4=year_sale,"SALE!","")) | E3: =IF(E4=year_refi,"REFINANCE!",IF(E4=year_sale,"SALE!","")) | F3: =IF(F4=year_refi,"REFINANCE!",IF(F4=year_sale,"SALE!","")) | G3: =IF(G4=year_refi,"REFINANCE!",IF(G4=year_sale,"SALE!","")) -> SALE! | H3: =IF(H4=year_refi,"REFINANCE!",IF(H4=year_sale,"SALE!","")) | I3: =IF(I4=year_refi,"REFINANCE!",IF(I4=year_sale,"SALE!","")) | J3: =IF(J4=year_refi,"REFINANCE!",IF(J4=year_sale,"SALE!","")) | ... L3: =IF(L4=year_refi,"REFINANCE!",IF(L4=year_sale,"SALE!",""))
B4: Projected Member Cash Flows and Returns | C4: 1 | D4: =C4+1 -> 2 | E4: =D4+1 -> 3 | F4: =E4+1 -> 4 | G4: =F4+1 -> 5 | H4: =G4+1 -> 6 | I4: =H4+1 -> 7 | J4: =I4+1 -> 8 | K4: =J4+1 -> 9 | L4: =K4+1 -> 10 | M4: Return $ | N4: Return %
B5: Beginning Member Capital Account Balance | C5: =Summary!$D$22 -> 0 | D5: =C$14 -> 0 | E5: =D$14 -> 0 | F5: =E$14 -> 0 | G5: =F$14 -> 0 | H5: =G$14 -> 0 | I5: =H$14 -> 0 | J5: =I$14 -> 0 | K5: =J$14 -> 0 | L5: =K$14 -> 0
B6: Member Cash Flow | C6: ='P&L'!D$51 -> 0 | D6: ='P&L'!F$51 -> 0 | E6: ='P&L'!H$51 -> 0 | F6: ='P&L'!J$51 -> 0 | G6: ='P&L'!L$51 -> 0 | H6: ='P&L'!N$51 -> 0 | I6: ='P&L'!P$51 -> 0 | J6: ='P&L'!R$51 -> 0 | K6: ='P&L'!T$51 -> 0 | L6: ='P&L'!V$51 -> 0 | M6: =SUM(C6:L6) -> 0
B7: Cash-on-Cash Return | C7: =IF(C$4<=year_sale,IF(C$5=0,"∞",C$6/C$5),0) -> ∞ | D7: =IF(D$4<=year_sale,IF(D$5=0,"∞",D$6/D$5),0) -> ∞ | E7: =IF(E$4<=year_sale,IF(E$5=0,"∞",E$6/E$5),0) -> ∞ | F7: =IF(F$4<=year_sale,IF(F$5=0,"∞",F$6/F$5),0) -> ∞ | G7: =IF(G$4<=year_sale,IF(G$5=0,"∞",G$6/G$5),0) -> ∞ | H7: =IF(H$4<=year_sale,IF(H$5=0,"∞",H$6/H$5),0) -> 0 | I7: =IF(I$4<=year_sale,IF(I$5=0,"∞",I$6/I$5),0) -> 0 | J7: =IF(J$4<=year_sale,IF(J$5=0,"∞",J$6/J$5),0) -> 0 | ... L7: =IF(L$4<=year_sale,IF(L$5=0,"∞",L$6/L$5),0) -> 0
B8: Average Cash-on-Cash Return to Date | C8: =IF(C$4<=year_sale,IF(C7="∞","∞",AVERAGE($C$7:C7)),0) -> ∞ | D8: =IF(D$4<=year_sale,IF(D7="∞","∞",AVERAGE($C$7:D7)),0) -> ∞ | E8: =IF(E$4<=year_sale,IF(E7="∞","∞",AVERAGE($C$7:E7)),0) -> ∞ | F8: =IF(F$4<=year_sale,IF(F7="∞","∞",AVERAGE($C$7:F7)),0) -> ∞ | G8: =IF(G$4<=year_sale,IF(G7="∞","∞",AVERAGE($C$7:G7)),0) -> ∞ | H8: =IF(H$4<=year_sale,IF(H7="∞","∞",AVERAGE($C$7:H7)),0) -> 0 | I8: =IF(I$4<=year_sale,IF(I7="∞","∞",AVERAGE($C$7:I7)),0) -> 0 | J8: =IF(J$4<=year_sale,IF(J7="∞","∞",AVERAGE($C$7:J7)),0) -> 0 | ... L8: =IF(L$4<=year_sale,IF(L7="∞","∞",AVERAGE($C$7:L7)),0) -> 0
B9: Preferred Return Deficiency | C9: =IF(C4=year_sale,'Exit Strategy'!$H$19,0) -> 0 | D9: =IF(D4=year_sale,'Exit Strategy'!$H$19,0) -> 0 | E9: =IF(E4=year_sale,'Exit Strategy'!$H$19,0) -> 0 | F9: =IF(F4=year_sale,'Exit Strategy'!$H$19,0) -> 0 | G9: =IF(G4=year_sale,'Exit Strategy'!$H$19,0) -> 0 | H9: =IF(H4=year_sale,'Exit Strategy'!$H$19,0) -> 0 | I9: =IF(I4=year_sale,'Exit Strategy'!$H$19,0) -> 0 | J9: =IF(J4=year_sale,'Exit Strategy'!$H$19,0) -> 0 | ... L9: =IF(L4=year_sale,'Exit Strategy'!$H$19,0) -> 0 | M9: =SUM(C9:L9) -> 0
B10: Net Proceeds/Profits from Refinance or Sale | C10: =IF(C$4=year_refi,'Exit Strategy'!$D$27,IF(C$4=year_sale,'Exit Strategy'!$H$23,0)) -> 0 | D10: =IF(D$4=year_refi,'Exit Strategy'!$D$27,IF(D$4=year_sale,'Exit Strategy'!$H$23,0)) -> 0 | E10: =IF(E$4=year_refi,'Exit Strategy'!$D$27,IF(E$4=year_sale,'Exit Strategy'!$H$23,0)) -> 0 | F10: =IF(F$4=year_refi,'Exit Strategy'!$D$27,IF(F$4=year_sale,'Exit Strategy'!$H$23,0)) -> 0 | G10: =IF(G$4=year_refi,'Exit Strategy'!$D$27,IF(G$4=year_sale,'Exit Strategy'!$H$23,0)) -> 0 | H10: =IF(H$4=year_refi,'Exit Strategy'!$D$27,IF(H$4=year_sale,'Exit Strategy'!$H$23,0)) -> 0 | I10: =IF(I$4=year_refi,'Exit Strategy'!$D$27,IF(I$4=year_sale,'Exit Strategy'!$H$23,0)) -> 0 | J10: =IF(J$4=year_refi,'Exit Strategy'!$D$27,IF(J$4=year_sale,'Exit Strategy'!$H$23,0)) -> 0 | ... L10: =IF(L$4=year_refi,'Exit Strategy'!$D$27,IF(L$4=year_sale,'Exit Strategy'!$H$23,0)) -> 0 | M10: =SUM(C10:L10) -> 0
B11: Average Annual Return to Date | C11: =IFERROR(IF(C$4<=year_sale,(SUM($C$6:C6)+SUM($C$10:C10)+C9)/$C$5/C$4,0),0) -> 0 | D11: =IFERROR(IF(D$4<=year_sale,(SUM($C$6:D6)+SUM($C$10:D10)+D9)/$C$5/D$4,0),0) -> 0 | E11: =IFERROR(IF(E$4<=year_sale,(SUM($C$6:E6)+SUM($C$10:E10)+E9)/$C$5/E$4,0),0) -> 0 | F11: =IFERROR(IF(F$4<=year_sale,(SUM($C$6:F6)+SUM($C$10:F10)+F9)/$C$5/F$4,0),0) -> 0 | G11: =IFERROR(IF(G$4<=year_sale,(SUM($C$6:G6)+SUM($C$10:G10)+G9)/$C$5/G$4,0),0) -> 0 | H11: =IFERROR(IF(H$4<=year_sale,(SUM($C$6:H6)+SUM($C$10:H10)+H9)/$C$5/H$4,0),0) -> 0 | I11: =IFERROR(IF(I$4<=year_sale,(SUM($C$6:I6)+SUM($C$10:I10)+I9)/$C$5/I$4,0),0) -> 0 | J11: =IFERROR(IF(J$4<=year_sale,(SUM($C$6:J6)+SUM($C$10:J10)+J9)/$C$5/J$4,0),0) -> 0 | ... L11: =IFERROR(IF(L$4<=year_sale,(SUM($C$6:L6)+SUM($C$10:L10)+L9)/$C$5/L$4,0),0) -> 0
B12: Return of Member Capital - P/I Escrow | C12: =IF(C$4>year_sale,0,IF(C$4=IF('Acquisition Costs'!$C$43<=0,year_sale,MIN('Acquisition Costs'!$C$43,year_sale)),'Acquisition Costs'!$D$44,0)) -> 0 | D12: =IF(D$4>year_sale,0,IF(D$4=IF('Acquisition Costs'!$C$43<=0,year_sale,MIN('Acquisition Costs'!$C$43,year_sale)),'Acquisition Costs'!$D$44,0)) -> 0 | E12: =IF(E$4>year_sale,0,IF(E$4=IF('Acquisition Costs'!$C$43<=0,year_sale,MIN('Acquisition Costs'!$C$43,year_sale)),'Acquisition Costs'!$D$44,0)) -> 0 | F12: =IF(F$4>year_sale,0,IF(F$4=IF('Acquisition Costs'!$C$43<=0,year_sale,MIN('Acquisition Costs'!$C$43,year_sale)),'Acquisition Costs'!$D$44,0)) -> 0 | G12: =IF(G$4>year_sale,0,IF(G$4=IF('Acquisition Costs'!$C$43<=0,year_sale,MIN('Acquisition Costs'!$C$43,year_sale)),'Acquisition Costs'!$D$44,0)) -> 0 | H12: =IF(H$4>year_sale,0,IF(H$4=IF('Acquisition Costs'!$C$43<=0,year_sale,MIN('Acquisition Costs'!$C$43,year_sale)),'Acquisition Costs'!$D$44,0)) -> 0 | I12: =IF(I$4>year_sale,0,IF(I$4=IF('Acquisition Costs'!$C$43<=0,year_sale,MIN('Acquisition Costs'!$C$43,year_sale)),'Acquisition Costs'!$D$44,0)) -> 0 | J12: =IF(J$4>year_sale,0,IF(J$4=IF('Acquisition Costs'!$C$43<=0,year_sale,MIN('Acquisition Costs'!$C$43,year_sale)),'Acquisition Costs'!$D$44,0)) -> 0 | ... L12: =IF(L$4>year_sale,0,IF(L$4=IF('Acquisition Costs'!$C$43<=0,year_sale,MIN('Acquisition Costs'!$C$43,year_sale)),'Acquisition Costs'!$D$44,0)) -> 0
B13: Return of Member Capital - Refinance or Sale | C13: =IF(C$4=year_refi,'Exit Strategy'!$D$21,IF(C$4=year_sale,'Exit Strategy'!$H$18,0)) -> 0 | D13: =IF(D$4=year_refi,'Exit Strategy'!$D$21,IF(D$4=year_sale,'Exit Strategy'!$H$18,0)) -> 0 | E13: =IF(E$4=year_refi,'Exit Strategy'!$D$21,IF(E$4=year_sale,'Exit Strategy'!$H$18,0)) -> 0 | F13: =IF(F$4=year_refi,'Exit Strategy'!$D$21,IF(F$4=year_sale,'Exit Strategy'!$H$18,0)) -> 0 | G13: =IF(G$4=year_refi,'Exit Strategy'!$D$21,IF(G$4=year_sale,'Exit Strategy'!$H$18,0)) -> 0 | H13: =IF(H$4=year_refi,'Exit Strategy'!$D$21,IF(H$4=year_sale,'Exit Strategy'!$H$18,0)) -> 0 | I13: =IF(I$4=year_refi,'Exit Strategy'!$D$21,IF(I$4=year_sale,'Exit Strategy'!$H$18,0)) -> 0 | J13: =IF(J$4=year_refi,'Exit Strategy'!$D$21,IF(J$4=year_sale,'Exit Strategy'!$H$18,0)) -> 0 | ... L13: =IF(L$4=year_refi,'Exit Strategy'!$D$21,IF(L$4=year_sale,'Exit Strategy'!$H$18,0)) -> 0
